2023-12-12 23:25:20,573 INFO    StreamThr :60979 [internal.py:wandb_internal():86] W&B internal server running at pid: 60979, started at: 2023-12-12 23:25:20.572455
2023-12-12 23:25:20,575 DEBUG   HandlerThread:60979 [handler.py:handle_request():144] handle_request: status
2023-12-12 23:25:20,632 INFO    WriterThread:60979 [datastore.py:open_for_write():85] open: /home/gridsan/yhuang1/songflow/transformer_flow/wandb/run-20231212_232520-ln62swi0/run-ln62swi0.wandb
2023-12-12 23:25:20,634 DEBUG   SenderThread:60979 [sender.py:send():380] send: header
2023-12-12 23:25:20,662 DEBUG   SenderThread:60979 [sender.py:send():380] send: run
2023-12-12 23:25:23,799 INFO    SenderThread:60979 [retry.py:__call__():172] Retry attempt failed:
Traceback (most recent call last):
  File "/home/gridsan/yhuang1/.local/lib/python3.9/site-packages/urllib3/connection.py", line 174, in _new_conn
    conn = connection.create_connection(
  File "/home/gridsan/yhuang1/.local/lib/python3.9/site-packages/urllib3/util/connection.py", line 95, in create_connection
    raise err
  File "/home/gridsan/yhuang1/.local/lib/python3.9/site-packages/urllib3/util/connection.py", line 85, in create_connection
    sock.connect(sa)
OSError: [Errno 101] Network is unreachable

During handling of the above exception, another exception occurred:

Traceback (most recent call last):
  File "/home/gridsan/yhuang1/.local/lib/python3.9/site-packages/urllib3/connectionpool.py", line 715, in urlopen
    httplib_response = self._make_request(
  File "/home/gridsan/yhuang1/.local/lib/python3.9/site-packages/urllib3/connectionpool.py", line 404, in _make_request
    self._validate_conn(conn)
  File "/home/gridsan/yhuang1/.local/lib/python3.9/site-packages/urllib3/connectionpool.py", line 1058, in _validate_conn
    conn.connect()
  File "/home/gridsan/yhuang1/.local/lib/python3.9/site-packages/urllib3/connection.py", line 363, in connect
    self.sock = conn = self._new_conn()
  File "/home/gridsan/yhuang1/.local/lib/python3.9/site-packages/urllib3/connection.py", line 186, in _new_conn
    raise NewConnectionError(
urllib3.exceptions.NewConnectionError: <urllib3.connection.HTTPSConnection object at 0x7f8ca6fbd6a0>: Failed to establish a new connection: [Errno 101] Network is unreachable

During handling of the above exception, another exception occurred:

Traceback (most recent call last):
  File "/home/gridsan/yhuang1/.local/lib/python3.9/site-packages/requests/adapters.py", line 486, in send
    resp = conn.urlopen(
  File "/home/gridsan/yhuang1/.local/lib/python3.9/site-packages/urllib3/connectionpool.py", line 799, in urlopen
    retries = retries.increment(
  File "/home/gridsan/yhuang1/.local/lib/python3.9/site-packages/urllib3/util/retry.py", line 592, in increment
    raise MaxRetryError(_pool, url, error or ResponseError(cause))
urllib3.exceptions.MaxRetryError: HTTPSConnectionPool(host='api.wandb.ai', port=443): Max retries exceeded with url: /graphql (Caused by NewConnectionError('<urllib3.connection.HTTPSConnection object at 0x7f8ca6fbd6a0>: Failed to establish a new connection: [Errno 101] Network is unreachable'))

During handling of the above exception, another exception occurred:

Traceback (most recent call last):
  File "/home/gridsan/yhuang1/.local/lib/python3.9/site-packages/wandb/sdk/lib/retry.py", line 131, in __call__
    result = self._call_fn(*args, **kwargs)
  File "/home/gridsan/yhuang1/.local/lib/python3.9/site-packages/wandb/sdk/internal/internal_api.py", line 366, in execute
    return self.client.execute(*args, **kwargs)  # type: ignore
  File "/home/gridsan/yhuang1/.local/lib/python3.9/site-packages/wandb/vendor/gql-0.2.0/wandb_gql/client.py", line 52, in execute
    result = self._get_result(document, *args, **kwargs)
  File "/home/gridsan/yhuang1/.local/lib/python3.9/site-packages/wandb/vendor/gql-0.2.0/wandb_gql/client.py", line 60, in _get_result
    return self.transport.execute(document, *args, **kwargs)
  File "/home/gridsan/yhuang1/.local/lib/python3.9/site-packages/wandb/sdk/lib/gql_request.py", line 58, in execute
    request = self.session.post(self.url, **post_args)
  File "/home/gridsan/yhuang1/.local/lib/python3.9/site-packages/requests/sessions.py", line 637, in post
    return self.request("POST", url, data=data, json=json, **kwargs)
  File "/home/gridsan/yhuang1/.local/lib/python3.9/site-packages/requests/sessions.py", line 589, in request
    resp = self.send(prep, **send_kwargs)
  File "/home/gridsan/yhuang1/.local/lib/python3.9/site-packages/requests/sessions.py", line 703, in send
    r = adapter.send(request, **kwargs)
  File "/home/gridsan/yhuang1/.local/lib/python3.9/site-packages/requests/adapters.py", line 519, in send
    raise ConnectionError(e, request=request)
requests.exceptions.ConnectionError: HTTPSConnectionPool(host='api.wandb.ai', port=443): Max retries exceeded with url: /graphql (Caused by NewConnectionError('<urllib3.connection.HTTPSConnection object at 0x7f8ca6fbd6a0>: Failed to establish a new connection: [Errno 101] Network is unreachable'))
2023-12-12 23:25:25,663 DEBUG   HandlerThread:60979 [handler.py:handle_request():144] handle_request: keepalive
2023-12-12 23:25:30,665 DEBUG   HandlerThread:60979 [handler.py:handle_request():144] handle_request: keepalive
2023-12-12 23:25:35,666 DEBUG   HandlerThread:60979 [handler.py:handle_request():144] handle_request: keepalive
2023-12-12 23:25:40,667 DEBUG   HandlerThread:60979 [handler.py:handle_request():144] handle_request: keepalive
2023-12-12 23:25:45,669 DEBUG   HandlerThread:60979 [handler.py:handle_request():144] handle_request: keepalive
2023-12-12 23:25:50,670 DEBUG   HandlerThread:60979 [handler.py:handle_request():144] handle_request: keepalive
2023-12-12 23:25:55,671 DEBUG   HandlerThread:60979 [handler.py:handle_request():144] handle_request: keepalive
2023-12-12 23:26:00,673 DEBUG   HandlerThread:60979 [handler.py:handle_request():144] handle_request: keepalive
2023-12-12 23:26:04,023 DEBUG   HandlerThread:60979 [handler.py:handle_request():144] handle_request: shutdown
2023-12-12 23:26:04,023 INFO    HandlerThread:60979 [handler.py:finish():844] shutting down handler
2023-12-12 23:26:04,669 INFO    WriterThread:60979 [datastore.py:close():294] close: /home/gridsan/yhuang1/songflow/transformer_flow/wandb/run-20231212_232520-ln62swi0/run-ln62swi0.wandb
